2025-01-23 01:35:48,921 - database:111 - DEBUG - Logging initialized for database - MainProcess:MainThread
2025-01-23 01:35:48,922 - app:30 - WARNING - Redis not available, falling back to in-memory queue - MainProcess:MainThread
2025-01-23 01:35:48,986 - database:111 - DEBUG - Logging initialized for database - MainProcess:MainThread
2025-01-23 01:35:48,989 - app:30 - WARNING - Redis not available, falling back to in-memory queue - MainProcess:MainThread
2025-01-23 01:35:49,451 - engineio.server:112 - INFO - Server initialized for eventlet. - MainProcess:MainThread
2025-01-23 01:35:49,455 - app:55 - INFO - Initializing Flask application - MainProcess:MainThread
2025-01-23 01:35:49,459 - app:70 - DEBUG - Application configuration loaded - MainProcess:MainThread
2025-01-23 01:35:49,553 - engineio.server:112 - INFO - Server initialized for eventlet. - MainProcess:MainThread
2025-01-23 01:35:49,555 - app:55 - INFO - Initializing Flask application - MainProcess:MainThread
2025-01-23 01:35:49,586 - app:70 - DEBUG - Application configuration loaded - MainProcess:MainThread
2025-01-23 01:35:49,752 - app:75 - INFO - Database initialized - MainProcess:MainThread
2025-01-23 01:35:49,753 - engineio.server:112 - INFO - Server initialized for eventlet. - MainProcess:MainThread
2025-01-23 01:35:49,753 - app:82 - INFO - Socket.IO initialized - MainProcess:MainThread
2025-01-23 01:35:49,773 - app:91 - INFO - CORS, Session, and CSRF protection initialized - MainProcess:MainThread
2025-01-23 01:35:49,808 - app:75 - INFO - Database initialized - MainProcess:MainThread
2025-01-23 01:35:49,811 - engineio.server:112 - INFO - Server initialized for eventlet. - MainProcess:MainThread
2025-01-23 01:35:49,812 - app:82 - INFO - Socket.IO initialized - MainProcess:MainThread
2025-01-23 01:35:49,839 - app:91 - INFO - CORS, Session, and CSRF protection initialized - MainProcess:MainThread
2025-01-23 01:35:52,761 - app:98 - INFO - Database tables created - MainProcess:MainThread
2025-01-23 01:35:52,783 - app:113 - INFO - Application initialized successfully - MainProcess:MainThread
2025-01-23 01:35:53,122 - app:98 - INFO - Database tables created - MainProcess:MainThread
2025-01-23 01:35:53,190 - app:113 - INFO - Application initialized successfully - MainProcess:MainThread
2025-01-23 01:35:53,361 - __main__:48 - INFO - Found in file: c2.1 concevoir des algorithmes qui répondent à des problèmes mathématiques donnés.
 - MainProcess:MainThread
2025-01-23 01:35:53,668 - __main__:108 - ERROR - Error during verification: The current Flask app is not registered with this 'SQLAlchemy' instance. Did you forget to call 'init_app', or did you create multiple 'SQLAlchemy' instances? - MainProcess:MainThread
Traceback (most recent call last):
  File "/home/runner/workspace/scripts/verify_c21.py", line 55, in verify_c21
    ).first()
      ^^^^^^^
  File "/home/runner/workspace/.pythonlibs/lib/python3.11/site-packages/sqlalchemy/orm/query.py", line 2728, in first
    return self.limit(1)._iter().first()  # type: ignore
           ^^^^^^^^^^^^^^^^^^^^^
  File "/home/runner/workspace/.pythonlibs/lib/python3.11/site-packages/sqlalchemy/orm/query.py", line 2827, in _iter
    result: Union[ScalarResult[_T], Result[_T]] = self.session.execute(
                                                  ^^^^^^^^^^^^^^^^^^^^^
  File "/home/runner/workspace/.pythonlibs/lib/python3.11/site-packages/sqlalchemy/orm/session.py", line 2362, in execute
    return self._execute_internal(
           ^^^^^^^^^^^^^^^^^^^^^^^
  File "/home/runner/workspace/.pythonlibs/lib/python3.11/site-packages/sqlalchemy/orm/session.py", line 2235, in _execute_internal
    bind = self.get_bind(**bind_arguments)
           ^^^^^^^^^^^^^^^^^^^^^^^^^^^^^^^
  File "/home/runner/workspace/.pythonlibs/lib/python3.11/site-packages/flask_sqlalchemy/session.py", line 53, in get_bind
    engines = self._db.engines
              ^^^^^^^^^^^^^^^^
  File "/home/runner/workspace/.pythonlibs/lib/python3.11/site-packages/flask_sqlalchemy/extension.py", line 690, in engines
    raise RuntimeError(
RuntimeError: The current Flask app is not registered with this 'SQLAlchemy' instance. Did you forget to call 'init_app', or did you create multiple 'SQLAlchemy' instances?
