2025-01-22 23:20:21,367 - engineio.server:112 - INFO - Server initialized for eventlet.
2025-01-22 23:20:21,368 - app:45 - INFO - Initializing Flask application
2025-01-22 23:20:21,371 - app:60 - DEBUG - Application configuration loaded
2025-01-22 23:20:21,500 - app:65 - INFO - Database initialized
2025-01-22 23:20:21,500 - engineio.server:112 - INFO - Server initialized for eventlet.
2025-01-22 23:20:21,500 - app:72 - INFO - Socket.IO initialized
2025-01-22 23:20:21,586 - app:81 - INFO - CORS, Session, and CSRF protection initialized
2025-01-22 23:20:22,049 - engineio.server:112 - INFO - Server initialized for eventlet.
2025-01-22 23:20:22,054 - app:45 - INFO - Initializing Flask application
2025-01-22 23:20:22,057 - app:60 - DEBUG - Application configuration loaded
2025-01-22 23:20:22,344 - app:65 - INFO - Database initialized
2025-01-22 23:20:22,355 - engineio.server:112 - INFO - Server initialized for eventlet.
2025-01-22 23:20:22,355 - app:72 - INFO - Socket.IO initialized
2025-01-22 23:20:22,428 - app:81 - INFO - CORS, Session, and CSRF protection initialized
2025-01-22 23:20:22,606 - app:88 - INFO - Database tables created
2025-01-22 23:20:22,614 - app:103 - INFO - Application initialized successfully
2025-01-22 23:20:22,731 - __main__:48 - INFO - Found in file: c2.1 concevoir des algorithmes qui répondent à des problèmes mathématiques donnés.

2025-01-22 23:20:22,812 - __main__:108 - ERROR - Error during verification: The current Flask app is not registered with this 'SQLAlchemy' instance. Did you forget to call 'init_app', or did you create multiple 'SQLAlchemy' instances?
Traceback (most recent call last):
  File "/home/runner/workspace/scripts/verify_c21.py", line 55, in verify_c21
    ).first()
      ^^^^^^^
  File "/home/runner/workspace/.pythonlibs/lib/python3.11/site-packages/sqlalchemy/orm/query.py", line 2728, in first
    return self.limit(1)._iter().first()  # type: ignore
           ^^^^^^^^^^^^^^^^^^^^^
  File "/home/runner/workspace/.pythonlibs/lib/python3.11/site-packages/sqlalchemy/orm/query.py", line 2827, in _iter
    result: Union[ScalarResult[_T], Result[_T]] = self.session.execute(
                                                  ^^^^^^^^^^^^^^^^^^^^^
  File "/home/runner/workspace/.pythonlibs/lib/python3.11/site-packages/sqlalchemy/orm/session.py", line 2362, in execute
    return self._execute_internal(
           ^^^^^^^^^^^^^^^^^^^^^^^
  File "/home/runner/workspace/.pythonlibs/lib/python3.11/site-packages/sqlalchemy/orm/session.py", line 2235, in _execute_internal
    bind = self.get_bind(**bind_arguments)
           ^^^^^^^^^^^^^^^^^^^^^^^^^^^^^^^
  File "/home/runner/workspace/.pythonlibs/lib/python3.11/site-packages/flask_sqlalchemy/session.py", line 53, in get_bind
    engines = self._db.engines
              ^^^^^^^^^^^^^^^^
  File "/home/runner/workspace/.pythonlibs/lib/python3.11/site-packages/flask_sqlalchemy/extension.py", line 690, in engines
    raise RuntimeError(
RuntimeError: The current Flask app is not registered with this 'SQLAlchemy' instance. Did you forget to call 'init_app', or did you create multiple 'SQLAlchemy' instances?
2025-01-22 23:20:23,423 - app:88 - INFO - Database tables created
2025-01-22 23:20:23,431 - app:103 - INFO - Application initialized successfully
2025-01-22 23:20:23,514 - __main__:47 - INFO - Starting ICS3U curriculum import process...
2025-01-22 23:20:23,553 - __main__:89 - ERROR - Import failed: The current Flask app is not registered with this 'SQLAlchemy' instance. Did you forget to call 'init_app', or did you create multiple 'SQLAlchemy' instances?
