2025-01-22 23:13:35,315 - app:43 - INFO - Initializing Flask application
2025-01-22 23:13:35,317 - app:58 - DEBUG - Application configuration loaded
2025-01-22 23:13:35,375 - app:63 - INFO - Database initialized
2025-01-22 23:13:35,476 - app:43 - INFO - Initializing Flask application
2025-01-22 23:13:35,479 - app:58 - DEBUG - Application configuration loaded
2025-01-22 23:13:35,610 - engineio.server:112 - INFO - Server initialized for eventlet.
2025-01-22 23:13:35,611 - app:70 - INFO - Socket.IO initialized
2025-01-22 23:13:35,615 - app:63 - INFO - Database initialized
2025-01-22 23:13:35,628 - app:79 - INFO - CORS, Session, and CSRF protection initialized
2025-01-22 23:13:35,636 - app:43 - INFO - Initializing Flask application
2025-01-22 23:13:35,638 - app:58 - DEBUG - Application configuration loaded
2025-01-22 23:13:35,759 - app:63 - INFO - Database initialized
2025-01-22 23:13:35,974 - engineio.server:112 - INFO - Server initialized for eventlet.
2025-01-22 23:13:35,975 - app:70 - INFO - Socket.IO initialized
2025-01-22 23:13:35,991 - app:79 - INFO - CORS, Session, and CSRF protection initialized
2025-01-22 23:13:36,212 - engineio.server:112 - INFO - Server initialized for eventlet.
2025-01-22 23:13:36,216 - app:70 - INFO - Socket.IO initialized
2025-01-22 23:13:36,231 - app:79 - INFO - CORS, Session, and CSRF protection initialized
2025-01-22 23:13:36,593 - app:86 - INFO - Database tables created
2025-01-22 23:13:36,594 - app:101 - INFO - Application initialized successfully
2025-01-22 23:13:36,802 - __main__:47 - INFO - Starting ICS3U curriculum import process...
2025-01-22 23:13:37,040 - app:86 - INFO - Database tables created
2025-01-22 23:13:37,110 - __main__:89 - ERROR - Import failed: The current Flask app is not registered with this 'SQLAlchemy' instance. Did you forget to call 'init_app', or did you create multiple 'SQLAlchemy' instances?
2025-01-22 23:13:37,088 - app:101 - INFO - Application initialized successfully
2025-01-22 23:13:37,113 - __main__:22 - INFO - Starting Flask server with SocketIO on port 5000
2025-01-22 23:13:37,113 - werkzeug:96 - WARNING -  * Debugger is active!
2025-01-22 23:13:37,114 - werkzeug:96 - INFO -  * Debugger PIN: 126-986-208
2025-01-22 23:13:37,299 - app:86 - INFO - Database tables created
2025-01-22 23:13:37,301 - app:101 - INFO - Application initialized successfully
2025-01-22 23:13:37,447 - __main__:47 - INFO - Starting ICS3U curriculum import process...
2025-01-22 23:13:37,485 - __main__:89 - ERROR - Import failed: The current Flask app is not registered with this 'SQLAlchemy' instance. Did you forget to call 'init_app', or did you create multiple 'SQLAlchemy' instances?
2025-01-22 23:13:37,521 - app:95 - DEBUG - Rendering console page
2025-01-22 23:13:38,344 - engineio.server:78 - INFO - TajsOOUHcqgF63rGAAAA: Sending packet OPEN data {'sid': 'TajsOOUHcqgF63rGAAAA', 'upgrades': [], 'pingTimeout': 60000, 'pingInterval': 25000, 'maxPayload': 100000000.0}
2025-01-22 23:13:38,345 - engineio.server:90 - INFO - TajsOOUHcqgF63rGAAAA: Received request to upgrade to websocket
2025-01-22 23:13:38,345 - engineio.server:219 - INFO - TajsOOUHcqgF63rGAAAA: Upgrade to websocket successful
2025-01-22 23:13:38,441 - engineio.server:39 - INFO - TajsOOUHcqgF63rGAAAA: Received packet MESSAGE data 0
2025-01-22 23:13:38,444 - socketio:84 - DEBUG - Socket.IO event handle_connect started at 2025-01-22 23:13:38.444684
2025-01-22 23:13:38,446 - socketio:85 - DEBUG - Event context: {'args': '(None,)', 'kwargs': '{}'}
2025-01-22 23:13:38,455 - socketio:43 - ERROR - Socket.IO error in handle_connect: setup_websocket_handlers.<locals>.handle_connect() takes 0 positional arguments but 1 was given
Traceback (most recent call last):
  File "/home/runner/workspace/utils/socketio_logger.py", line 87, in wrapper
    result = func(*args, **kwargs)
             ^^^^^^^^^^^^^^^^^^^^^
TypeError: setup_websocket_handlers.<locals>.handle_connect() takes 0 positional arguments but 1 was given
2025-01-22 23:13:38,457 - socketio:99 - ERROR - Error in Socket.IO event handle_connect after 0.011s: setup_websocket_handlers.<locals>.handle_connect() takes 0 positional arguments but 1 was given
Traceback (most recent call last):
  File "/home/runner/workspace/utils/socketio_logger.py", line 87, in wrapper
    result = func(*args, **kwargs)
             ^^^^^^^^^^^^^^^^^^^^^
TypeError: setup_websocket_handlers.<locals>.handle_connect() takes 0 positional arguments but 1 was given
2025-01-22 23:13:38,458 - socketio:84 - DEBUG - Socket.IO event handle_connect started at 2025-01-22 23:13:38.458456
2025-01-22 23:13:38,458 - socketio:85 - DEBUG - Event context: {'args': '()', 'kwargs': '{}'}
2025-01-22 23:13:38,458 - app:120 - INFO - Client connected: v2_l2DqK1Em9i9mzAAAB
2025-01-22 23:13:38,458 - socketio:108 - INFO - New connection established. Total connections: 1
2025-01-22 23:13:38,459 - socketio:110 - DEBUG - Client info: {'sid': 'v2_l2DqK1Em9i9mzAAAB', 'remote_addr': '172.31.196.32', 'user_agent': 'Mozilla/5.0 (Macintosh; Intel Mac OS X 10_15_7) AppleWebKit/537.36 (KHTML, like Gecko) Chrome/131.0.0.0 Safari/537.36'}
2025-01-22 23:13:38,459 - socketio.server:164 - INFO - emitting event "connection_established" to v2_l2DqK1Em9i9mzAAAB [/]
2025-01-22 23:13:38,460 - engineio.server:78 - INFO - TajsOOUHcqgF63rGAAAA: Sending packet MESSAGE data 2["connection_established",{"status":"connected","sid":"v2_l2DqK1Em9i9mzAAAB"}]
2025-01-22 23:13:38,460 - socketio:31 - DEBUG - Event tracked: handle_connect, Duration: 0.002s, Context: {'args': '()', 'kwargs': '{}'}
2025-01-22 23:13:38,464 - socketio:92 - DEBUG - Socket.IO event handle_connect completed in 0.002s
2025-01-22 23:13:38,464 - socketio:93 - DEBUG - Event result: None
2025-01-22 23:13:38,464 - engineio.server:78 - INFO - TajsOOUHcqgF63rGAAAA: Sending packet MESSAGE data 0{"sid":"v2_l2DqK1Em9i9mzAAAB"}
