2025-01-22 23:12:11,335 - app:43 - INFO - Initializing Flask application
2025-01-22 23:12:11,340 - app:58 - DEBUG - Application configuration loaded
2025-01-22 23:12:11,435 - app:63 - INFO - Database initialized
2025-01-22 23:12:11,751 - app:43 - INFO - Initializing Flask application
2025-01-22 23:12:11,754 - app:58 - DEBUG - Application configuration loaded
2025-01-22 23:12:11,939 - engineio.server:112 - INFO - Server initialized for eventlet.
2025-01-22 23:12:11,940 - app:70 - INFO - Socket.IO initialized
2025-01-22 23:12:11,970 - app:79 - INFO - CORS, Session, and CSRF protection initialized
2025-01-22 23:12:11,996 - app:63 - INFO - Database initialized
2025-01-22 23:12:12,270 - engineio.server:112 - INFO - Server initialized for eventlet.
2025-01-22 23:12:12,277 - app:70 - INFO - Socket.IO initialized
2025-01-22 23:12:12,310 - app:79 - INFO - CORS, Session, and CSRF protection initialized
2025-01-22 23:12:12,952 - app:86 - INFO - Database tables created
2025-01-22 23:12:12,957 - app:101 - INFO - Application initialized successfully
2025-01-22 23:12:13,017 - __main__:48 - INFO - Found in file: c2.1 concevoir des algorithmes qui répondent à des problèmes mathématiques donnés.

2025-01-22 23:12:13,056 - __main__:108 - ERROR - Error during verification: The current Flask app is not registered with this 'SQLAlchemy' instance. Did you forget to call 'init_app', or did you create multiple 'SQLAlchemy' instances?
Traceback (most recent call last):
  File "/home/runner/workspace/scripts/verify_c21.py", line 55, in verify_c21
    ).first()
      ^^^^^^^
  File "/home/runner/workspace/.pythonlibs/lib/python3.11/site-packages/sqlalchemy/orm/query.py", line 2728, in first
    return self.limit(1)._iter().first()  # type: ignore
           ^^^^^^^^^^^^^^^^^^^^^
  File "/home/runner/workspace/.pythonlibs/lib/python3.11/site-packages/sqlalchemy/orm/query.py", line 2827, in _iter
    result: Union[ScalarResult[_T], Result[_T]] = self.session.execute(
                                                  ^^^^^^^^^^^^^^^^^^^^^
  File "/home/runner/workspace/.pythonlibs/lib/python3.11/site-packages/sqlalchemy/orm/session.py", line 2362, in execute
    return self._execute_internal(
           ^^^^^^^^^^^^^^^^^^^^^^^
  File "/home/runner/workspace/.pythonlibs/lib/python3.11/site-packages/sqlalchemy/orm/session.py", line 2235, in _execute_internal
    bind = self.get_bind(**bind_arguments)
           ^^^^^^^^^^^^^^^^^^^^^^^^^^^^^^^
  File "/home/runner/workspace/.pythonlibs/lib/python3.11/site-packages/flask_sqlalchemy/session.py", line 53, in get_bind
    engines = self._db.engines
              ^^^^^^^^^^^^^^^^
  File "/home/runner/workspace/.pythonlibs/lib/python3.11/site-packages/flask_sqlalchemy/extension.py", line 690, in engines
    raise RuntimeError(
RuntimeError: The current Flask app is not registered with this 'SQLAlchemy' instance. Did you forget to call 'init_app', or did you create multiple 'SQLAlchemy' instances?
2025-01-22 23:12:13,286 - app:86 - INFO - Database tables created
2025-01-22 23:12:13,286 - app:101 - INFO - Application initialized successfully
2025-01-22 23:12:13,403 - __main__:333 - INFO - Starting ICD2O curriculum import process...
2025-01-22 23:12:13,454 - __main__:58 - ERROR - Error clearing existing data: The current Flask app is not registered with this 'SQLAlchemy' instance. Did you forget to call 'init_app', or did you create multiple 'SQLAlchemy' instances?
2025-01-22 23:12:13,461 - __main__:387 - ERROR - Import failed: The current Flask app is not registered with this 'SQLAlchemy' instance. Did you forget to call 'init_app', or did you create multiple 'SQLAlchemy' instances?
