2025-01-23 02:59:55,096 - database:111 - DEBUG - Logging initialized for database - MainProcess:MainThread
2025-01-23 02:59:55,099 - app:30 - WARNING - Redis not available, falling back to in-memory queue - MainProcess:MainThread
2025-01-23 02:59:55,100 - database:111 - DEBUG - Logging initialized for database - MainProcess:MainThread
2025-01-23 02:59:55,101 - app:30 - WARNING - Redis not available, falling back to in-memory queue - MainProcess:MainThread
2025-01-23 02:59:55,689 - engineio.server:112 - INFO - Server initialized for eventlet. - MainProcess:MainThread
2025-01-23 02:59:55,690 - app:55 - INFO - Initializing Flask application - MainProcess:MainThread
2025-01-23 02:59:55,691 - app:70 - DEBUG - Application configuration loaded - MainProcess:MainThread
2025-01-23 02:59:56,041 - app:75 - INFO - Database initialized - MainProcess:MainThread
2025-01-23 02:59:56,042 - engineio.server:112 - INFO - Server initialized for eventlet. - MainProcess:MainThread
2025-01-23 02:59:56,043 - app:82 - INFO - Socket.IO initialized - MainProcess:MainThread
2025-01-23 02:59:56,132 - app:91 - INFO - CORS, Session, and CSRF protection initialized - MainProcess:MainThread
2025-01-23 02:59:56,540 - engineio.server:112 - INFO - Server initialized for eventlet. - MainProcess:MainThread
2025-01-23 02:59:56,541 - app:55 - INFO - Initializing Flask application - MainProcess:MainThread
2025-01-23 02:59:56,556 - app:70 - DEBUG - Application configuration loaded - MainProcess:MainThread
2025-01-23 02:59:57,013 - app:75 - INFO - Database initialized - MainProcess:MainThread
2025-01-23 02:59:57,015 - engineio.server:112 - INFO - Server initialized for eventlet. - MainProcess:MainThread
2025-01-23 02:59:57,017 - app:82 - INFO - Socket.IO initialized - MainProcess:MainThread
2025-01-23 02:59:57,058 - app:91 - INFO - CORS, Session, and CSRF protection initialized - MainProcess:MainThread
2025-01-23 02:59:59,679 - app:98 - INFO - Database tables created - MainProcess:MainThread
2025-01-23 02:59:59,682 - app:113 - INFO - Application initialized successfully - MainProcess:MainThread
2025-01-23 03:00:00,015 - app:98 - INFO - Database tables created - MainProcess:MainThread
2025-01-23 03:00:00,017 - app:113 - INFO - Application initialized successfully - MainProcess:MainThread
2025-01-23 03:00:00,413 - __main__:48 - INFO - Found in file: c2.1 concevoir des algorithmes qui répondent à des problèmes mathématiques donnés.
 - MainProcess:MainThread
2025-01-23 03:00:00,543 - __main__:108 - ERROR - Error during verification: The current Flask app is not registered with this 'SQLAlchemy' instance. Did you forget to call 'init_app', or did you create multiple 'SQLAlchemy' instances? - MainProcess:MainThread
Traceback (most recent call last):
  File "/home/runner/workspace/scripts/verify_c21.py", line 55, in verify_c21
    ).first()
      ^^^^^^^
  File "/home/runner/workspace/.pythonlibs/lib/python3.11/site-packages/sqlalchemy/orm/query.py", line 2728, in first
    return self.limit(1)._iter().first()  # type: ignore
           ^^^^^^^^^^^^^^^^^^^^^
  File "/home/runner/workspace/.pythonlibs/lib/python3.11/site-packages/sqlalchemy/orm/query.py", line 2827, in _iter
    result: Union[ScalarResult[_T], Result[_T]] = self.session.execute(
                                                  ^^^^^^^^^^^^^^^^^^^^^
  File "/home/runner/workspace/.pythonlibs/lib/python3.11/site-packages/sqlalchemy/orm/session.py", line 2362, in execute
    return self._execute_internal(
           ^^^^^^^^^^^^^^^^^^^^^^^
  File "/home/runner/workspace/.pythonlibs/lib/python3.11/site-packages/sqlalchemy/orm/session.py", line 2235, in _execute_internal
    bind = self.get_bind(**bind_arguments)
           ^^^^^^^^^^^^^^^^^^^^^^^^^^^^^^^
  File "/home/runner/workspace/.pythonlibs/lib/python3.11/site-packages/flask_sqlalchemy/session.py", line 53, in get_bind
    engines = self._db.engines
              ^^^^^^^^^^^^^^^^
  File "/home/runner/workspace/.pythonlibs/lib/python3.11/site-packages/flask_sqlalchemy/extension.py", line 690, in engines
    raise RuntimeError(
RuntimeError: The current Flask app is not registered with this 'SQLAlchemy' instance. Did you forget to call 'init_app', or did you create multiple 'SQLAlchemy' instances?
