2025-01-22 23:09:06,153 - __main__:89 - ERROR - Import failed: The current Flask app is not registered with this 'SQLAlchemy' instance. Did you forget to call 'init_app', or did you create multiple 'SQLAlchemy' instances?
2025-01-22 23:09:06,295 - __main__:89 - ERROR - Import failed: The current Flask app is not registered with this 'SQLAlchemy' instance. Did you forget to call 'init_app', or did you create multiple 'SQLAlchemy' instances?
2025-01-22 23:09:06,552 - __main__:108 - ERROR - Error during verification: The current Flask app is not registered with this 'SQLAlchemy' instance. Did you forget to call 'init_app', or did you create multiple 'SQLAlchemy' instances?
Traceback (most recent call last):
  File "/home/runner/workspace/scripts/verify_c21.py", line 55, in verify_c21
    ).first()
      ^^^^^^^
  File "/home/runner/workspace/.pythonlibs/lib/python3.11/site-packages/sqlalchemy/orm/query.py", line 2728, in first
    return self.limit(1)._iter().first()  # type: ignore
           ^^^^^^^^^^^^^^^^^^^^^
  File "/home/runner/workspace/.pythonlibs/lib/python3.11/site-packages/sqlalchemy/orm/query.py", line 2827, in _iter
    result: Union[ScalarResult[_T], Result[_T]] = self.session.execute(
                                                  ^^^^^^^^^^^^^^^^^^^^^
  File "/home/runner/workspace/.pythonlibs/lib/python3.11/site-packages/sqlalchemy/orm/session.py", line 2362, in execute
    return self._execute_internal(
           ^^^^^^^^^^^^^^^^^^^^^^^
  File "/home/runner/workspace/.pythonlibs/lib/python3.11/site-packages/sqlalchemy/orm/session.py", line 2235, in _execute_internal
    bind = self.get_bind(**bind_arguments)
           ^^^^^^^^^^^^^^^^^^^^^^^^^^^^^^^
  File "/home/runner/workspace/.pythonlibs/lib/python3.11/site-packages/flask_sqlalchemy/session.py", line 53, in get_bind
    engines = self._db.engines
              ^^^^^^^^^^^^^^^^
  File "/home/runner/workspace/.pythonlibs/lib/python3.11/site-packages/flask_sqlalchemy/extension.py", line 690, in engines
    raise RuntimeError(
RuntimeError: The current Flask app is not registered with this 'SQLAlchemy' instance. Did you forget to call 'init_app', or did you create multiple 'SQLAlchemy' instances?
2025-01-22 23:09:06,794 - socketio:43 - ERROR - Socket.IO error in handle_connect: setup_websocket_handlers.<locals>.handle_connect() takes 0 positional arguments but 1 was given
Traceback (most recent call last):
  File "/home/runner/workspace/utils/socketio_logger.py", line 87, in wrapper
    result = func(*args, **kwargs)
             ^^^^^^^^^^^^^^^^^^^^^
TypeError: setup_websocket_handlers.<locals>.handle_connect() takes 0 positional arguments but 1 was given
2025-01-22 23:09:06,795 - socketio:99 - ERROR - Error in Socket.IO event handle_connect after 0.001s: setup_websocket_handlers.<locals>.handle_connect() takes 0 positional arguments but 1 was given
Traceback (most recent call last):
  File "/home/runner/workspace/utils/socketio_logger.py", line 87, in wrapper
    result = func(*args, **kwargs)
             ^^^^^^^^^^^^^^^^^^^^^
TypeError: setup_websocket_handlers.<locals>.handle_connect() takes 0 positional arguments but 1 was given
2025-01-22 23:09:07,288 - __main__:58 - ERROR - Error clearing existing data: The current Flask app is not registered with this 'SQLAlchemy' instance. Did you forget to call 'init_app', or did you create multiple 'SQLAlchemy' instances?
2025-01-22 23:09:07,295 - __main__:387 - ERROR - Import failed: The current Flask app is not registered with this 'SQLAlchemy' instance. Did you forget to call 'init_app', or did you create multiple 'SQLAlchemy' instances?
2025-01-22 23:09:13,897 - socketio:43 - ERROR - Socket.IO error in handle_connect: setup_websocket_handlers.<locals>.handle_connect() takes 0 positional arguments but 1 was given
Traceback (most recent call last):
  File "/home/runner/workspace/utils/socketio_logger.py", line 87, in wrapper
    result = func(*args, **kwargs)
             ^^^^^^^^^^^^^^^^^^^^^
TypeError: setup_websocket_handlers.<locals>.handle_connect() takes 0 positional arguments but 1 was given
2025-01-22 23:09:13,930 - socketio:99 - ERROR - Error in Socket.IO event handle_connect after 0.003s: setup_websocket_handlers.<locals>.handle_connect() takes 0 positional arguments but 1 was given
Traceback (most recent call last):
  File "/home/runner/workspace/utils/socketio_logger.py", line 87, in wrapper
    result = func(*args, **kwargs)
             ^^^^^^^^^^^^^^^^^^^^^
TypeError: setup_websocket_handlers.<locals>.handle_connect() takes 0 positional arguments but 1 was given
2025-01-22 23:09:15,194 - socketio:43 - ERROR - Socket.IO error in handle_connect: setup_websocket_handlers.<locals>.handle_connect() takes 0 positional arguments but 1 was given
Traceback (most recent call last):
  File "/home/runner/workspace/utils/socketio_logger.py", line 87, in wrapper
    result = func(*args, **kwargs)
             ^^^^^^^^^^^^^^^^^^^^^
TypeError: setup_websocket_handlers.<locals>.handle_connect() takes 0 positional arguments but 1 was given
2025-01-22 23:09:15,194 - socketio:99 - ERROR - Error in Socket.IO event handle_connect after 0.001s: setup_websocket_handlers.<locals>.handle_connect() takes 0 positional arguments but 1 was given
Traceback (most recent call last):
  File "/home/runner/workspace/utils/socketio_logger.py", line 87, in wrapper
    result = func(*args, **kwargs)
             ^^^^^^^^^^^^^^^^^^^^^
TypeError: setup_websocket_handlers.<locals>.handle_connect() takes 0 positional arguments but 1 was given
2025-01-22 23:09:15,385 - socketio:43 - ERROR - Socket.IO error in handle_connect: setup_websocket_handlers.<locals>.handle_connect() takes 0 positional arguments but 1 was given
Traceback (most recent call last):
  File "/home/runner/workspace/utils/socketio_logger.py", line 87, in wrapper
    result = func(*args, **kwargs)
             ^^^^^^^^^^^^^^^^^^^^^
TypeError: setup_websocket_handlers.<locals>.handle_connect() takes 0 positional arguments but 1 was given
2025-01-22 23:09:15,391 - socketio:99 - ERROR - Error in Socket.IO event handle_connect after 0.002s: setup_websocket_handlers.<locals>.handle_connect() takes 0 positional arguments but 1 was given
Traceback (most recent call last):
  File "/home/runner/workspace/utils/socketio_logger.py", line 87, in wrapper
    result = func(*args, **kwargs)
             ^^^^^^^^^^^^^^^^^^^^^
TypeError: setup_websocket_handlers.<locals>.handle_connect() takes 0 positional arguments but 1 was given
2025-01-22 23:09:15,744 - socketio:43 - ERROR - Socket.IO error in handle_disconnect: setup_websocket_handlers.<locals>.handle_disconnect() takes 0 positional arguments but 1 was given
Traceback (most recent call last):
  File "/home/runner/workspace/utils/socketio_logger.py", line 87, in wrapper
    result = func(*args, **kwargs)
             ^^^^^^^^^^^^^^^^^^^^^
TypeError: setup_websocket_handlers.<locals>.handle_disconnect() takes 0 positional arguments but 1 was given
2025-01-22 23:09:15,746 - socketio:99 - ERROR - Error in Socket.IO event handle_disconnect after 0.001s: setup_websocket_handlers.<locals>.handle_disconnect() takes 0 positional arguments but 1 was given
Traceback (most recent call last):
  File "/home/runner/workspace/utils/socketio_logger.py", line 87, in wrapper
    result = func(*args, **kwargs)
             ^^^^^^^^^^^^^^^^^^^^^
TypeError: setup_websocket_handlers.<locals>.handle_disconnect() takes 0 positional arguments but 1 was given
2025-01-22 23:09:15,749 - socketio:134 - ERROR - socketio_error: Socket.IO error: setup_websocket_handlers.<locals>.handle_disconnect() takes 0 positional arguments but 1 was given
Traceback (most recent call last):
  File "/home/runner/workspace/.pythonlibs/lib/python3.11/site-packages/flask_socketio/__init__.py", line 835, in _handle_event
    ret = handler(*args)
          ^^^^^^^^^^^^^^
  File "/home/runner/workspace/utils/socketio_logger.py", line 87, in wrapper
    result = func(*args, **kwargs)
             ^^^^^^^^^^^^^^^^^^^^^
TypeError: setup_websocket_handlers.<locals>.handle_disconnect() takes 0 positional arguments but 1 was given
2025-01-22 23:09:15,765 - socketio:43 - ERROR - Socket.IO error in socketio_error: Socket.IO error: setup_websocket_handlers.<locals>.handle_disconnect() takes 0 positional arguments but 1 was given
Traceback (most recent call last):
  File "/home/runner/workspace/.pythonlibs/lib/python3.11/site-packages/flask_socketio/__init__.py", line 835, in _handle_event
    ret = handler(*args)
          ^^^^^^^^^^^^^^
  File "/home/runner/workspace/utils/socketio_logger.py", line 87, in wrapper
    result = func(*args, **kwargs)
             ^^^^^^^^^^^^^^^^^^^^^
TypeError: setup_websocket_handlers.<locals>.handle_disconnect() takes 0 positional arguments but 1 was given
2025-01-22 23:09:35,506 - socketio:134 - ERROR - compilation_error: Error in compile_and_run: 'Logger' object has no attribute 'log_compilation_start'
Traceback (most recent call last):
  File "/home/runner/workspace/app.py", line 161, in handle_compile_and_run
    compiler_logger.log_compilation_start(compilation_session_id, code)
    ^^^^^^^^^^^^^^^^^^^^^^^^^^^^^^^^^^^^^
AttributeError: 'Logger' object has no attribute 'log_compilation_start'
2025-01-22 23:09:35,506 - socketio:43 - ERROR - Socket.IO error in compilation_error: Error in compile_and_run: 'Logger' object has no attribute 'log_compilation_start'
Traceback (most recent call last):
  File "/home/runner/workspace/app.py", line 161, in handle_compile_and_run
    compiler_logger.log_compilation_start(compilation_session_id, code)
    ^^^^^^^^^^^^^^^^^^^^^^^^^^^^^^^^^^^^^
AttributeError: 'Logger' object has no attribute 'log_compilation_start'
2025-01-22 23:10:05,506 - socketio:43 - ERROR - Socket.IO error in handle_disconnect: setup_websocket_handlers.<locals>.handle_disconnect() takes 0 positional arguments but 1 was given
Traceback (most recent call last):
  File "/home/runner/workspace/utils/socketio_logger.py", line 87, in wrapper
    result = func(*args, **kwargs)
             ^^^^^^^^^^^^^^^^^^^^^
TypeError: setup_websocket_handlers.<locals>.handle_disconnect() takes 0 positional arguments but 1 was given
2025-01-22 23:10:05,507 - socketio:99 - ERROR - Error in Socket.IO event handle_disconnect after 0.000s: setup_websocket_handlers.<locals>.handle_disconnect() takes 0 positional arguments but 1 was given
Traceback (most recent call last):
  File "/home/runner/workspace/utils/socketio_logger.py", line 87, in wrapper
    result = func(*args, **kwargs)
             ^^^^^^^^^^^^^^^^^^^^^
TypeError: setup_websocket_handlers.<locals>.handle_disconnect() takes 0 positional arguments but 1 was given
2025-01-22 23:10:05,507 - socketio:134 - ERROR - socketio_error: Socket.IO error: setup_websocket_handlers.<locals>.handle_disconnect() takes 0 positional arguments but 1 was given
Traceback (most recent call last):
  File "/home/runner/workspace/.pythonlibs/lib/python3.11/site-packages/flask_socketio/__init__.py", line 835, in _handle_event
    ret = handler(*args)
          ^^^^^^^^^^^^^^
  File "/home/runner/workspace/utils/socketio_logger.py", line 87, in wrapper
    result = func(*args, **kwargs)
             ^^^^^^^^^^^^^^^^^^^^^
TypeError: setup_websocket_handlers.<locals>.handle_disconnect() takes 0 positional arguments but 1 was given
2025-01-22 23:10:05,508 - socketio:43 - ERROR - Socket.IO error in socketio_error: Socket.IO error: setup_websocket_handlers.<locals>.handle_disconnect() takes 0 positional arguments but 1 was given
Traceback (most recent call last):
  File "/home/runner/workspace/.pythonlibs/lib/python3.11/site-packages/flask_socketio/__init__.py", line 835, in _handle_event
    ret = handler(*args)
          ^^^^^^^^^^^^^^
  File "/home/runner/workspace/utils/socketio_logger.py", line 87, in wrapper
    result = func(*args, **kwargs)
             ^^^^^^^^^^^^^^^^^^^^^
TypeError: setup_websocket_handlers.<locals>.handle_disconnect() takes 0 positional arguments but 1 was given
2025-01-22 23:10:06,913 - socketio:43 - ERROR - Socket.IO error in handle_connect: setup_websocket_handlers.<locals>.handle_connect() takes 0 positional arguments but 1 was given
Traceback (most recent call last):
  File "/home/runner/workspace/utils/socketio_logger.py", line 87, in wrapper
    result = func(*args, **kwargs)
             ^^^^^^^^^^^^^^^^^^^^^
TypeError: setup_websocket_handlers.<locals>.handle_connect() takes 0 positional arguments but 1 was given
2025-01-22 23:10:06,913 - socketio:99 - ERROR - Error in Socket.IO event handle_connect after 0.000s: setup_websocket_handlers.<locals>.handle_connect() takes 0 positional arguments but 1 was given
Traceback (most recent call last):
  File "/home/runner/workspace/utils/socketio_logger.py", line 87, in wrapper
    result = func(*args, **kwargs)
             ^^^^^^^^^^^^^^^^^^^^^
TypeError: setup_websocket_handlers.<locals>.handle_connect() takes 0 positional arguments but 1 was given
2025-01-22 23:10:57,980 - __main__:108 - ERROR - Error during verification: The current Flask app is not registered with this 'SQLAlchemy' instance. Did you forget to call 'init_app', or did you create multiple 'SQLAlchemy' instances?
Traceback (most recent call last):
  File "/home/runner/workspace/scripts/verify_c21.py", line 55, in verify_c21
    ).first()
      ^^^^^^^
  File "/home/runner/workspace/.pythonlibs/lib/python3.11/site-packages/sqlalchemy/orm/query.py", line 2728, in first
    return self.limit(1)._iter().first()  # type: ignore
           ^^^^^^^^^^^^^^^^^^^^^
  File "/home/runner/workspace/.pythonlibs/lib/python3.11/site-packages/sqlalchemy/orm/query.py", line 2827, in _iter
    result: Union[ScalarResult[_T], Result[_T]] = self.session.execute(
                                                  ^^^^^^^^^^^^^^^^^^^^^
  File "/home/runner/workspace/.pythonlibs/lib/python3.11/site-packages/sqlalchemy/orm/session.py", line 2362, in execute
    return self._execute_internal(
           ^^^^^^^^^^^^^^^^^^^^^^^
  File "/home/runner/workspace/.pythonlibs/lib/python3.11/site-packages/sqlalchemy/orm/session.py", line 2235, in _execute_internal
    bind = self.get_bind(**bind_arguments)
           ^^^^^^^^^^^^^^^^^^^^^^^^^^^^^^^
  File "/home/runner/workspace/.pythonlibs/lib/python3.11/site-packages/flask_sqlalchemy/session.py", line 53, in get_bind
    engines = self._db.engines
              ^^^^^^^^^^^^^^^^
  File "/home/runner/workspace/.pythonlibs/lib/python3.11/site-packages/flask_sqlalchemy/extension.py", line 690, in engines
    raise RuntimeError(
RuntimeError: The current Flask app is not registered with this 'SQLAlchemy' instance. Did you forget to call 'init_app', or did you create multiple 'SQLAlchemy' instances?
2025-01-22 23:10:58,024 - __main__:58 - ERROR - Error clearing existing data: The current Flask app is not registered with this 'SQLAlchemy' instance. Did you forget to call 'init_app', or did you create multiple 'SQLAlchemy' instances?
2025-01-22 23:10:58,025 - __main__:387 - ERROR - Import failed: The current Flask app is not registered with this 'SQLAlchemy' instance. Did you forget to call 'init_app', or did you create multiple 'SQLAlchemy' instances?
2025-01-22 23:10:58,438 - __main__:89 - ERROR - Import failed: The current Flask app is not registered with this 'SQLAlchemy' instance. Did you forget to call 'init_app', or did you create multiple 'SQLAlchemy' instances?
2025-01-22 23:10:59,248 - __main__:89 - ERROR - Import failed: The current Flask app is not registered with this 'SQLAlchemy' instance. Did you forget to call 'init_app', or did you create multiple 'SQLAlchemy' instances?
2025-01-22 23:11:04,826 - socketio:43 - ERROR - Socket.IO error in handle_connect: setup_websocket_handlers.<locals>.handle_connect() takes 0 positional arguments but 1 was given
Traceback (most recent call last):
  File "/home/runner/workspace/utils/socketio_logger.py", line 87, in wrapper
    result = func(*args, **kwargs)
             ^^^^^^^^^^^^^^^^^^^^^
TypeError: setup_websocket_handlers.<locals>.handle_connect() takes 0 positional arguments but 1 was given
2025-01-22 23:11:04,827 - socketio:99 - ERROR - Error in Socket.IO event handle_connect after 0.001s: setup_websocket_handlers.<locals>.handle_connect() takes 0 positional arguments but 1 was given
Traceback (most recent call last):
  File "/home/runner/workspace/utils/socketio_logger.py", line 87, in wrapper
    result = func(*args, **kwargs)
             ^^^^^^^^^^^^^^^^^^^^^
TypeError: setup_websocket_handlers.<locals>.handle_connect() takes 0 positional arguments but 1 was given
2025-01-22 23:11:05,742 - socketio:43 - ERROR - Socket.IO error in handle_connect: setup_websocket_handlers.<locals>.handle_connect() takes 0 positional arguments but 1 was given
Traceback (most recent call last):
  File "/home/runner/workspace/utils/socketio_logger.py", line 87, in wrapper
    result = func(*args, **kwargs)
             ^^^^^^^^^^^^^^^^^^^^^
TypeError: setup_websocket_handlers.<locals>.handle_connect() takes 0 positional arguments but 1 was given
2025-01-22 23:11:05,743 - socketio:99 - ERROR - Error in Socket.IO event handle_connect after 0.000s: setup_websocket_handlers.<locals>.handle_connect() takes 0 positional arguments but 1 was given
Traceback (most recent call last):
  File "/home/runner/workspace/utils/socketio_logger.py", line 87, in wrapper
    result = func(*args, **kwargs)
             ^^^^^^^^^^^^^^^^^^^^^
TypeError: setup_websocket_handlers.<locals>.handle_connect() takes 0 positional arguments but 1 was given
2025-01-22 23:11:06,190 - socketio:43 - ERROR - Socket.IO error in handle_connect: setup_websocket_handlers.<locals>.handle_connect() takes 0 positional arguments but 1 was given
Traceback (most recent call last):
  File "/home/runner/workspace/utils/socketio_logger.py", line 87, in wrapper
    result = func(*args, **kwargs)
             ^^^^^^^^^^^^^^^^^^^^^
TypeError: setup_websocket_handlers.<locals>.handle_connect() takes 0 positional arguments but 1 was given
2025-01-22 23:11:06,192 - socketio:99 - ERROR - Error in Socket.IO event handle_connect after 0.001s: setup_websocket_handlers.<locals>.handle_connect() takes 0 positional arguments but 1 was given
Traceback (most recent call last):
  File "/home/runner/workspace/utils/socketio_logger.py", line 87, in wrapper
    result = func(*args, **kwargs)
             ^^^^^^^^^^^^^^^^^^^^^
TypeError: setup_websocket_handlers.<locals>.handle_connect() takes 0 positional arguments but 1 was given
2025-01-22 23:11:06,343 - socketio:43 - ERROR - Socket.IO error in handle_disconnect: setup_websocket_handlers.<locals>.handle_disconnect() takes 0 positional arguments but 1 was given
Traceback (most recent call last):
  File "/home/runner/workspace/utils/socketio_logger.py", line 87, in wrapper
    result = func(*args, **kwargs)
             ^^^^^^^^^^^^^^^^^^^^^
TypeError: setup_websocket_handlers.<locals>.handle_disconnect() takes 0 positional arguments but 1 was given
2025-01-22 23:11:06,344 - socketio:99 - ERROR - Error in Socket.IO event handle_disconnect after 0.001s: setup_websocket_handlers.<locals>.handle_disconnect() takes 0 positional arguments but 1 was given
Traceback (most recent call last):
  File "/home/runner/workspace/utils/socketio_logger.py", line 87, in wrapper
    result = func(*args, **kwargs)
             ^^^^^^^^^^^^^^^^^^^^^
TypeError: setup_websocket_handlers.<locals>.handle_disconnect() takes 0 positional arguments but 1 was given
2025-01-22 23:11:06,344 - socketio:134 - ERROR - socketio_error: Socket.IO error: setup_websocket_handlers.<locals>.handle_disconnect() takes 0 positional arguments but 1 was given
Traceback (most recent call last):
  File "/home/runner/workspace/.pythonlibs/lib/python3.11/site-packages/flask_socketio/__init__.py", line 835, in _handle_event
    ret = handler(*args)
          ^^^^^^^^^^^^^^
  File "/home/runner/workspace/utils/socketio_logger.py", line 87, in wrapper
    result = func(*args, **kwargs)
             ^^^^^^^^^^^^^^^^^^^^^
TypeError: setup_websocket_handlers.<locals>.handle_disconnect() takes 0 positional arguments but 1 was given
2025-01-22 23:11:06,345 - socketio:43 - ERROR - Socket.IO error in socketio_error: Socket.IO error: setup_websocket_handlers.<locals>.handle_disconnect() takes 0 positional arguments but 1 was given
Traceback (most recent call last):
  File "/home/runner/workspace/.pythonlibs/lib/python3.11/site-packages/flask_socketio/__init__.py", line 835, in _handle_event
    ret = handler(*args)
          ^^^^^^^^^^^^^^
  File "/home/runner/workspace/utils/socketio_logger.py", line 87, in wrapper
    result = func(*args, **kwargs)
             ^^^^^^^^^^^^^^^^^^^^^
TypeError: setup_websocket_handlers.<locals>.handle_disconnect() takes 0 positional arguments but 1 was given
