BuildError
werkzeug.routing.exceptions.BuildError: Could not build url for endpoint 'auth.login'. Did you mean 'custom_static' instead?

Traceback (most recent call last)
File "/home/runner/codecrafthub/app.py", line 87, in index
return render_template('index.html', lang=lang)
       ^^^^^^^^^^^^^^^^^^^^^^^^^^^^^^^^^^^^^^^^
File "/home/runner/codecrafthub/.pythonlibs/lib/python3.11/site-packages/flask/templating.py", line 150, in render_template
return _render(app, template, context)
       ^^^^^^^^^^^^^^^^^^^^^^^^^^^^^^^
File "/home/runner/codecrafthub/.pythonlibs/lib/python3.11/site-packages/flask/templating.py", line 131, in _render
rv = template.render(context)
     ^^^^^^^^^^^^^^^^^^^^^^^^
File "/home/runner/codecrafthub/.pythonlibs/lib/python3.11/site-packages/jinja2/environment.py", line 1295, in render
self.environment.handle_exception()
^^^^^^^^^^^^^^^^^^^^^^^^^^^^^^^^^^^
File "/home/runner/codecrafthub/.pythonlibs/lib/python3.11/site-packages/jinja2/environment.py", line 942, in handle_exception
raise rewrite_traceback_stack(source=source)
^^^^^^^^^^^^^^^^^^^^^^^^^^^^^^^^^^^^^^^^^^^^
File "/home/runner/codecrafthub/templates/index.html", line 2, in top-level template code
{% extends "base.html" %}
File "/home/runner/codecrafthub/templates/base.html", line 42, in top-level template code
<a class="nav-link" href="{{ url_for('auth.login') }}">
File "/home/runner/codecrafthub/.pythonlibs/lib/python3.11/site-packages/flask/app.py", line 1121, in url_for
return self.handle_url_build_error(error, endpoint, values)
       ^^^^^^^^^^^^^^^^^^^^^^^^^^^^^^^^^^^^^^^^^^^^^^^^^^^^
File "/home/runner/codecrafthub/.pythonlibs/lib/python3.11/site-packages/flask/app.py", line 1110, in url_for
rv = url_adapter.build(  # type: ignore[union-attr]
     
File "/home/runner/codecrafthub/.pythonlibs/lib/python3.11/site-packages/werkzeug/routing/map.py", line 924, in build
raise BuildError(endpoint, values, method, self)
^^^^^^^^^^^^^^^^^^^^^^^^^^^^^^^^^^^^^^^^^^^^^^^^
During handling of the above exception, another exception occurred:
File "/home/runner/codecrafthub/.pythonlibs/lib/python3.11/site-packages/flask/app.py", line 1536, in __call__
return self.wsgi_app(environ, start_response)
       ^^^^^^^^^^^^^^^^^^^^^^^^^^^^^^^^^^^^^^
File "/home/runner/codecrafthub/.pythonlibs/lib/python3.11/site-packages/flask/app.py", line 1514, in wsgi_app
response = self.handle_exception(e)
           ^^^^^^^^^^^^^^^^^^^^^^^^
File "/home/runner/codecrafthub/.pythonlibs/lib/python3.11/site-packages/flask/app.py", line 1511, in wsgi_app
response = self.full_dispatch_request()
           ^^^^^^^^^^^^^^^^^^^^^^^^^^^^
File "/home/runner/codecrafthub/.pythonlibs/lib/python3.11/site-packages/flask/app.py", line 919, in full_dispatch_request
rv = self.handle_user_exception(e)
     ^^^^^^^^^^^^^^^^^^^^^^^^^^^^^
File "/home/runner/codecrafthub/.pythonlibs/lib/python3.11/site-packages/flask/app.py", line 917, in full_dispatch_request
rv = self.dispatch_request()
     ^^^^^^^^^^^^^^^^^^^^^^^
File "/home/runner/codecrafthub/.pythonlibs/lib/python3.11/site-packages/flask/app.py", line 902, in dispatch_request
return self.ensure_sync(self.view_functions[rule.endpoint])(**view_args)  # type: ignore[no-any-return]
       ^^^^^^^^^^^^^^^^^^^^^^^^^^^^^^^^^^^^^^^^^^^^^^^^^^^^^^^^^^^^^^^^^
File "/home/runner/codecrafthub/app.py", line 90, in index
return render_template('errors/500.html', lang=lang), 500
       ^^^^^^^^^^^^^^^^^^^^^^^^^^^^^^^^^^^^^^^^^^^^^
File "/home/runner/codecrafthub/.pythonlibs/lib/python3.11/site-packages/flask/templating.py", line 150, in render_template
return _render(app, template, context)
       ^^^^^^^^^^^^^^^^^^^^^^^^^^^^^^^
File "/home/runner/codecrafthub/.pythonlibs/lib/python3.11/site-packages/flask/templating.py", line 131, in _render
rv = template.render(context)
     ^^^^^^^^^^^^^^^^^^^^^^^^
File "/home/runner/codecrafthub/.pythonlibs/lib/python3.11/site-packages/jinja2/environment.py", line 1295, in render
self.environment.handle_exception()
^^^^^^^^^^^^^^^^^^^^^^^^^^^^^^^^^^^
File "/home/runner/codecrafthub/.pythonlibs/lib/python3.11/site-packages/jinja2/environment.py", line 942, in handle_exception
raise rewrite_traceback_stack(source=source)
^^^^^^^^^^^^^^^^^^^^^^^^^^^^^^^^^^^^^^^^^^^^
File "/home/runner/codecrafthub/templates/errors/500.html", line 2, in top-level template code
{% extends "base.html" %}
File "/home/runner/codecrafthub/templates/base.html", line 42, in top-level template code
<a class="nav-link" href="{{ url_for('auth.login') }}">
File "/home/runner/codecrafthub/.pythonlibs/lib/python3.11/site-packages/flask/app.py", line 1121, in url_for
return self.handle_url_build_error(error, endpoint, values)
       ^^^^^^^^^^^^^^^^^^^^^^^^^^^^^^^^^^^^^^^^^^^^^^^^^^^^
File "/home/runner/codecrafthub/.pythonlibs/lib/python3.11/site-packages/flask/app.py", line 1110, in url_for
rv = url_adapter.build(  # type: ignore[union-attr]
     
File "/home/runner/codecrafthub/.pythonlibs/lib/python3.11/site-packages/werkzeug/routing/map.py", line 924, in build
raise BuildError(endpoint, values, method, self)
^^^^^^^^^^^^^^^^^^^^^^^^^^^^^^^^^^^^^^^^^^^^^^^^
werkzeug.routing.exceptions.BuildError: Could not build url for endpoint 'auth.login'. Did you mean 'custom_static' instead?
The debugger caught an exception in your WSGI application. You can now look at the traceback which led to the error.
To switch between the interactive traceback and the plaintext one, you can click on the "Traceback" headline. From the text traceback you can also create a paste of it.

Brought to you by DON'T PANIC, your friendly Werkzeug powered traceback interpreter.